<?xml version='1.0'?>
<sdf version='1.4'>
  <model name="threepi">
    <static>false</static>
    <link name='chassis'>
      <pose>0 0 .01444 0 0 0</pose>
      <inertial>
        <pose>0.03 0 0 0 0 0</pose>
        <mass>90</mass>
        <inertia>
          <ixx>0.050645</ixx>
          <ixy>0.0</ixy>
          <ixz>0.0</ixz>
          <iyy>0.050645</iyy>
          <iyz>0.0</iyz>
          <izz>0.099557</izz>
        </inertia>
      </inertial>
      
      <collision name='collision'>
        <geometry>
          <cylinder>
            <radius>.04713</radius>
            <length>.0034</length>
          </cylinder>   
        </geometry>
      </collision>
      
      <visual name='visual'>
        <geometry>
          <cylinder>
            <radius>.04713</radius>
            <length>.0034</length>
          </cylinder>
        </geometry>
        <material>
          <ambient>0.7 0.7 0.7 1</ambient>
          <diffuse>1 0 0 1</diffuse>
          <specular>0.1 0.1 0.1 1</specular>
          <emissive>0 0 0 0</emissive>
        </material>
      </visual>    
      
      <visual name='box_1'>
        <pose>.0225 0 .0077 0 0 0</pose>
        <geometry>
		      <box>
            <size>.023 .053 .012</size>
          </box>
        </geometry>
      </visual>
      
      <visual name='box_2'>
        <pose>-.0225 0 .0077 0 0 0</pose>
          <geometry>
		        <box>
              <size>.023 .053 .012</size>
            </box>
          </geometry>
      </visual>
           
      <collision name='caster_collision'>
        <pose>0.034 0 -0.00807 0 0 0</pose>
          <geometry>
            <sphere>
              <radius>.00637</radius>
            </sphere>
          </geometry>
          <surface>
            <friction>
              <ode>
                <mu>0.0</mu>
                <mu2>0.0</mu2>
                <slip1>0.0</slip1>
                <slip2>0.0</slip2>
              </ode>
            </friction>
          </surface>
        </collision>

        <visual name='caster_visual'>
          <pose>0.034 0 -0.00807 0 0 0</pose>
            <geometry>
              <sphere>
                <radius>.00637</radius>
              </sphere>
            </geometry>
            <material>
              <ambient>0.8 0.8 0 0.8</ambient>
              <diffuse>0.8 0 0 1</diffuse>
              <specular>0.1 0.1 0.1 1</specular>
              <emissive>0 0 0 0</emissive>
           </material>
       </visual>
     </link>

     <link name="left_wheel">
       <pose>0 0.05043 0.0156 0 1.5707 1.5707</pose>
         <collision name="collision">
           <geometry>
             <cylinder>
               <radius>.0156</radius>
               <length>.0066</length>
             </cylinder>
           </geometry>
         </collision>
         <visual name="visual">
           <geometry>
             <cylinder>
               <radius>.0156</radius>
               <length>.0066</length>
             </cylinder>
           </geometry>
           <material>
             <ambient>0 0 0 1</ambient>
             <diffuse>0 0 0 1</diffuse>
             <specular>0.1 0.1 0.1 1</specular>
             <emissive>0 0 0 0</emissive>
           </material>
         </visual>
         <inertial>
           <mass>4</mass>
           <inertia>
             <ixx>0.00027008332</ixx>
             <ixy>0.0</ixy>
             <ixz>0.0</ixz>
             <iyy>0.00027008332</iyy>
             <iyz>0.0</iyz>
             <izz>0.000512</izz>
           </inertia>
         </inertial>
     </link>

     <link name="right_wheel">
       <pose>0 -0.05043 0.0156 0 1.5707 1.5707</pose>
       <collision name="collision">
         <geometry>
           <cylinder>
             <radius>.0156</radius>
             <length>.0066</length>
           </cylinder>
         </geometry>
       </collision>       
       <visual name="visual">
         <geometry>
           <cylinder>
             <radius>.0156</radius>
             <length>.0066</length>
           </cylinder>
         </geometry>
         <material>
           <ambient>0 0 0 1</ambient>
           <diffuse>0 0 0 1</diffuse>
           <specular>0.1 0.1 0.1 1</specular>
           <emissive>0 0 0 0</emissive>
         </material>
       </visual>
       <inertial>
         <mass>4</mass>
         <inertia>
           <ixx>0.00027008332</ixx>
           <ixy>0.0</ixy>
           <ixz>0.0</ixz>
           <iyy>0.00027008332</iyy>
           <iyz>0.0</iyz>
           <izz>0.000512</izz>
         </inertia>
       </inertial>
    </link>

    <joint type="revolute" name="left_wheel_joint">
       <pose>0 0 0 0 0 0</pose>
       <child>left_wheel</child>
       <parent>chassis</parent>
         <axis>
           <xyz>0 1 0</xyz>
           <dynamics>
             <damping>0.01</damping>
           </dynamics>
         </axis>
    </joint>

    <joint type="revolute" name="right_wheel_joint">
      <pose>0 0 0 0 0 0</pose>
      <child>right_wheel</child>
      <parent>chassis</parent>
        <axis>
          <xyz>0 1 0</xyz>
          <dynamics>
            <damping>0.01</damping>
          </dynamics>
        </axis>
    </joint>
      
      <plugin name="ThreePiCTRL_POS" filename="libThreePi_controller_POS.so"/>
  </model>
</sdf>
