<?xml version='1.0'?>
<sdf version='1.4'>
  <model name="1DPlane">
    <static>false</static>
    <link name="base">
      <pose>0 0 0.05 0 0 0</pose>
      
      <collision name='collision_base'>
        <geometry>
          <box>
            <size>0.5 0.5 0.1</size>
          </box>
        </geometry> 
      </collision>
      
      <collision name='collision_support'>
        <pose>0 0 0.25 0 0 0</pose>
        <geometry>
          <box>
            <size>0.1 0.1 0.3</size>
          </box>
        </geometry>
      </collision>
      
      <visual name='visual_base'>
        <geometry>
          <box>
            <size>0.5 0.5 0.1</size>
          </box>
        </geometry> 
      </visual>
      
      <visual name='visual_support'>
        <pose>0 0 0.2 0 0 0</pose>
        <geometry>
          <box>
            <size>0.1 0.1 0.4</size>
          </box>
        </geometry>
      </visual>
    </link>
    
    <link name='plane'>
      <pose>0.0 0.0 0.5 0 0 0</pose>
      <collision name='collision_plane'>
        <geometry>
          <box>
            <size>1 1 0.01</size>
          </box>
        </geometry>
      </collision>
      
      <visual name='visual_plane'>
        <geometry>
          <box>
            <size>1 1 0.00635</size>
          </box>
        </geometry>
      </visual>
    </link>
    
    <joint type='revolute' name='main_joint'>
      <pose>0.0 0.0 0.0 0 0 0</pose>
      <child>plane</child>
      <parent>base</parent>
      <axis>
        <xyz>0 1 0</xyz>
        <dynamics>
          <damping>0.1</damping>
        </dynamics>
        <limit>
          <lower>-0.785398</lower>
          <upper>0.785398</upper>
        </limit>
      </axis>
    </joint>
  </model>
</sdf>
