<?xml version='1.0'?>
<sdf version='1.4'>
  <model name="1DPlane">
    <static>false</static>
    <link name="base">
      <pose>0 0 0.05 0 0 0</pose>
      
      <collision name='collision_base'>
        <geometry>
          <box>
            <size>0.5 0.5 0.1</size>
          </box>
        </geometry> 
      </collision>
      
      <collision name='collision_support'>
        <pose>0 0 0.25 0 0 0</pose>
        <geometry>
          <box>
            <size>0.1 0.1 0.3</size>
          </box>
        </geometry>
      </collision>
      
      <visual name='visual_base'>
        <geometry>
          <box>
            <size>0.5 0.5 0.1</size>
          </box>
        </geometry> 
      </visual>
      
      <visual name='visual_support'>
        <pose>0 0 0.2 0 0 0</pose>
        <geometry>
          <box>
            <size>0.1 0.1 0.4</size>
          </box>
        </geometry>
      </visual>
    </link>
    
    <link name='plane'>
      <pose>0.0 0.0 0.5 0 0 0</pose>
      <inertial>
        <pose>0 0 0 0 0 0</pose>
        <mass>7780</mass>
        <inertia>
          <ixx>240.02556</ixx>
          <ixy>0.0</ixy>
          <ixz>0.0</ixz>
          <iyy>240.02556</iyy>
          <iyz>0.0</iyz>
          <izz>479.999</izz>
        </inertia>
      </inertial>
      
      <collision name='collision_plane'>
        <geometry>
          <box>
            <size>1 1 0.01</size>
          </box>
        </geometry>
      </collision>
        
      <visual name='visual_plane'>
        <geometry>
          <box>
            <size>1 1 0.00635</size>
          </box>
        </geometry>
      </visual>
    </link>
    
    <joint type='revolute' name='main_joint'>
      <pose>0.0 0.0 0.0 0 0 0</pose>
      <child>plane</child>
      <parent>base</parent>
      <axis>
        <xyz>0 1 0</xyz>
        <dynamics>
          <damping>0.7</damping>
        </dynamics>
        <limit>
          <lower>-0.52359877559</lower>
          <upper>0.52359877559</upper>
        </limit>
      </axis>
    </joint>
    
    <joint type='revolute' name='fix_to_ground'>
      <parent>world</parent>
      <child>base</child>
      <axis>
        <xyz>1 0 0</xyz>
        <limit>
          <lower>0.0</lower>
          <upper>0.0</uppper>
        </limit>
      </axis>
    </joint>
  </model>
</sdf>
